python: can't open file '/Users/ziqi/Work/pyc/workaround/refcountChecker/LLMPlugin/RC_openai.py': [Errno 2] No such file or directory
[0;33m
====================
Content below is generated by LLVM Refcnt pass
====================
[0m[0;33m<init_pass> use settings from settings.json
[0m[0;33m<init_pass> initialization done
[0m[0;33m<runOnModule> analysis mode: intra
[0m[0;33m<runOnModule> entry function: sum_list
[0m[0;33m<refcntAnalysis> memref: AAMemRef__No__0
[0m[0;33m<refcntAnalysis> memref: AAMemRef__No__1
[0m[0;33m<refcntAnalysis> memref: AAMemRef__No__0
[0m[0;33m<refcntAnalysis> memref: AAMemRef__No__2
[0m[0;33m<refcntAnalysis> memref: AAMemRef__No__2
[0m[0;33m<refcntAnalysis> memref: AAMemRef__No__3
[0m[0;33m<refcntAnalysis> memref: AAMemRef__No__4
[0m[0;33m<refcntAnalysis> memref: AAMemRef__No__4
[0m[0;33m<refcntAnalysis> memref: AAMemRef__No__2
[0m[0;33m<refcntAnalysis> memref: AAMemRef__No__0
[0m[0;33m<refcntAnalysis> memref: AAMemRef__No__4
[0m[0;33m<refcntAnalysis> memref: AAMemRef__No__5
[0m[0;33m<refcntAnalysis> memref: AAMemRef__No__5
[0m[0;33m<refcntAnalysis> memref: AAMemRef__No__1
[0m[0;33m<refcntAnalysis> memref: AAMemRef__No__1
[0m[0;33m<refcntAnalysis> memref: AAMemRef__No__4
[0m[0;33m<refcntAnalysis> memref: AAMemRef__No__4
[0m[0;33m<refcntAnalysis> memref: AAMemRef__No__5
[0m[0;33m<refcntAnalysis> memref: AAMemRef__No__1
[0m[0;33m<refcntAnalysis> memref: AAMemRef__No__3
[0m[0;33m<refcntAnalysis> memref: AAMemRef__No__3
[0m[0;33m<doAnalysis> intra analysis started
[0m[0;33m<doAnalysis> function: sum_list
[0m[0;33m<intraAnalysis>---------AA sets begin---------
AAMemRef__No__5(size:4): 
item, call5, , , 
AAMemRef__No__4(size:6): 
i, , , , , inc, 
AAMemRef__No__2(size:4): 
n, conv, , , 
AAMemRef__No__1(size:5): 
total, , , add, , 
AAMemRef__No__3(size:4): 
retval, , , , 
AAMemRef__No__0(size:4): 
list, list.addr, , , 

<doAnalysis>---------AA sets end---------
[0m[0;33m<transferNode> call: PyList_Size
[0m[0;33m<transferNode> call: PyList_GetItem
[0m[0;33m<transferNode> memref: AAMemRef__No__5
[0m[0;33m<transferNode> call: PyLong_AsLong
[0m[0;33m<getAPIType> Not supported API: PyLong_AsLong
[0m[0;33m<transferNode> call: _Py_DECREF
[0m[0;33m<transferNode> memref: AAMemRef__No__5
[0m[0;33m<transferNode> call: PyList_GetItem
[0m[0;33m<transferNode> memref: AAMemRef__No__5
[0m[0;33m<transferNode> call: PyLong_AsLong
[0m[0;33m<getAPIType> Not supported API: PyLong_AsLong
[0m[0;33m<transferNode> call: _Py_DECREF
[0m[0;33m<transferNode> memref: AAMemRef__No__5
[0m[0;33m<bugReport> bugs found, Function: sum_list
[0m[0;33m<bugReport> Error:UAF;Memory:AAMemRef__No__5;Function:sum_list;Line:0;Variable:call5;
[0m[0;33m<bugReport> Error:UAF;Memory:AAMemRef__No__5;Function:sum_list;Line:0;Variable:item;
[0m